Workbook
Name Segment_Centre_Intérêt: #N/A
Name Segment_Réseau_Social: #N/A
Name Segment_Segmentation_du_Public___Âge: #N/A
Name Segment_Segmentation_du_Public___Sexe: #N/A

Sheet DATA
A1: ID Campagne | B1: Réseau Social | C1: Date de Début | D1: Date de Fin | E1: Budget de la Campagne (€) | F1: Nombre de Vues | G1: Nombre de Clics | H1: Taux de Conversion (%) | I1: Ventes Générées (€) | J1: ROI (%) | K1: Segmentation du Public - Âge | L1: Segmentation du Public - Sexe | M1: Centre Intérêt
A2: 1 | B2: Facebook | C2: 44293.363 | D2: 44540.355 | E2: 1394 | F2: 57620 | G2: 297 | H2: 0.0052 | I2: 3046 | J2: =(I2-E2)/E2 -> 1.1850789 | K2: 18-24 | L2: Homme | M2: Beauté
A3: 2 | B3: Twitter | C3: 44408.361 | D3: 44415.361 | E3: 5874 | F3: 84725 | G3: 1771 | H3: 0.0209 | I3: 28067 | J3: =(I3-E3)/E3 -> 3.778175 | K3: 18-24 | L3: Femme | M3: Beauté
A4: 3 | B4: Twitter | C4: 44256.696 | D4: 44514.307 | E4: 636 | F4: 48993 | G4: 2785 | H4: 0.0568 | I4: 2412 | J4: =(I4-E4)/E4 -> 2.7924528 | K4: 25-34 | L4: Femme | M4: Santé
A5: 4 | B5: Facebook | C5: 44486.347 | D5: 44493.347 | E5: 6773 | F5: 68398 | G5: 706 | H5: 0.0103 | I5: 21632 | J5: =(I5-E5)/E5 -> 2.193858 | K5: 25-34 | L5: Homme | M5: Lifestyle
A6: 5 | B6: Facebook | C6: 44285.474 | D6: 44513.962 | E6: 3919 | F6: 67439 | G6: 2220 | H6: 0.0329 | I6: 4710 | J6: =(I6-E6)/E6 -> 0.2018372 | K6: 25-34 | L6: Femme | M6: Santé
A7: 6 | B7: Facebook | C7: 44458.929 | D7: 44465.929 | E7: 668 | F7: 96952 | G7: 4442 | H7: 0.0458 | I7: 802 | J7: =(I7-E7)/E7 -> 0.2005988 | K7: 55+ | L7: Femme | M7: Beauté
A8: 7 | B8: Instagram | C8: 44201.335 | D8: 44229.789 | E8: 6504 | F8: 16352 | G8: 1259 | H8: 0.077 | I8: 4951 | J8: =(I8-E8)/E8 -> -0.23877614 | K8: 25-34 | L8: Femme | M8: Fitness
A9: 8 | B9: Twitter | C9: 44254.067 | D9: 44297.687 | E9: 3352 | F9: 65022 | G9: 1831 | H9: 0.0282 | I9: 14741 | J9: =(I9-E9)/E9 -> 3.397673 | K9: 55+ | L9: Femme | M9: Beauté
A10: 9 | B10: Facebook | C10: 44332.474 | D10: 44546.528 | E10: 4919 | F10: 91616 | G10: 2361 | H10: 0.0258 | I10: 15765 | J10: =(I10-E10)/E10 -> 2.2049197 | K10: 18-24 | L10: Femme | M10: Lifestyle
A11: 10 | B11: Facebook | C11: 44228.269 | D11: 44251.811 | E11: 8539 | F11: 90935 | G11: 3495 | H11: 0.0384 | I11: 31477 | J11: =(I11-E11)/E11 -> 2.686263 | K11: 55+ | L11: Femme | M11: Lifestyle
A12: 11 | B12: Instagram | C12: 44329.355 | D12: 44468.29 | E12: 9200 | F12: 15297 | G12: 2475 | H12: 0.1618 | I12: 5452 | J12: =(I12-E12)/E12 -> -0.4073913 | K12: 45-54 | L12: Homme | M12: Mode
A13: 12 | B13: Facebook | C13: 44366.744 | D13: 44472.622 | E13: 3686 | F13: 6896 | G13: 695 | H13: 0.1008 | I13: 17930 | J13: =(I13-E13)/E13 -> 3.8643516 | K13: 35-44 | L13: Femme | M13: Fitness
... A106: 105 | B106: Twitter | C106: 45306 | D106: 45328 | E106: 5950 | F106: 31976 | G106: 6496 | H106: 0.2032 | I106: 27275 | J106: =(I106-E106)/E106 -> 3.5840336 | K106: 18-24 | L106: Femme | M106: Beauté

Sheet REPORTING
B2: Nombre Campagnes par Réseau
B3: Réseau Social | C3: Nombre de Campagne
B4: Facebook | C4: =COUNTIF(DATA!B2:B100000,"Facebook") -> 36
B5: Twitter | C5: =COUNTIF(DATA!B3:B100001,"Twitter") -> 28
B6: Instagram | C6: =COUNTIF(DATA!B4:B100002,"Instagram") -> 41
B10: Budget et Ventes par Réseau
B11: Réseau Social | C11: Budget investi | D11: Total des ventes générées | E11: Différence entre ventes et budget
B12: Facebook | C12: =SUMIF(DATA!B2:B1000,"Facebook",DATA!E2:E1000) -> 184371 | D12: =SUMIF(DATA!B2:B1000,"Facebook",DATA!I2:I1000) -> 497803 | E12: =D12-C12 -> 313432
B13: Twitter | C13: =SUMIF(DATA!B3:B1001,"Twitter",DATA!E3:E1001) -> 139315 | D13: =SUMIF(DATA!B3:B1001,"Twitter",DATA!I3:I1001) -> 411222 | E13: =D13-C13 -> 271907
B14: Instagram | C14: =SUMIF(DATA!B4:B1002,"Instagram",DATA!E4:E1002) -> 237570 | D14: =SUMIF(DATA!B4:B1002,"Instagram",DATA!I4:I1002) -> 561028 | E14: =D14-C14 -> 323458
B18: Performances par Âge
B19: Tranche d'âge | C19: Nombre total de campagne | D19: Total des vues | E19: Total des ventes générées | F19: Taux de conversion moyen | G19: ROI Moyen
B20: 18-24 | C20: =COUNTIF(DATA!K2:K1000,B20) -> 25 | D20: =SUMIF(DATA!K2:K10000,REPORTING!B20,DATA!F2:F1000) -> 1301419 | E20: =SUMIF(DATA!K2:K1000,REPORTING!B20,DATA!I2:I10000) -> 398209 | F20: =AVERAGEIF(DATA!K2:K10000,REPORTING!B20,DATA!H2:H1000) -> 0.11618 | G20: =AVERAGEIF(DATA!K2:K10000,REPORTING!B20,DATA!J2:J10000) -> 1.9001934
B21: 25-34 | C21: =COUNTIF(DATA!K3:K1001,B21) -> 23 | D21: =SUMIF(DATA!K3:K10001,REPORTING!B21,DATA!F3:F1001) -> 1014367 | E21: =SUMIF(DATA!K3:K1001,REPORTING!B21,DATA!I3:I10001) -> 274382 | F21: =AVERAGEIF(DATA!K3:K10001,REPORTING!B21,DATA!H3:H1001) -> 0.1353913 | G21: =AVERAGEIF(DATA!K3:K10001,REPORTING!B21,DATA!J3:J10001) -> 1.413926
B22: 35-44 | C22: =COUNTIF(DATA!K4:K1002,B22) -> 18 | D22: =SUMIF(DATA!K4:K10002,REPORTING!B22,DATA!F4:F1002) -> 949678 | E22: =SUMIF(DATA!K4:K1002,REPORTING!B22,DATA!I4:I10002) -> 270590 | F22: =AVERAGEIF(DATA!K4:K10002,REPORTING!B22,DATA!H4:H1002) -> 0.065416667 | G22: =AVERAGEIF(DATA!K4:K10002,REPORTING!B22,DATA!J4:J10002) -> 1.3913549
B23: 45-54 | C23: =COUNTIF(DATA!K5:K1003,B23) -> 22 | D23: =SUMIF(DATA!K5:K10003,REPORTING!B23,DATA!F5:F1003) -> 1010551 | E23: =SUMIF(DATA!K5:K1003,REPORTING!B23,DATA!I5:I10003) -> 274285 | F23: =AVERAGEIF(DATA!K5:K10003,REPORTING!B23,DATA!H5:H1003) -> 0.080086364 | G23: =AVERAGEIF(DATA!K5:K10003,REPORTING!B23,DATA!J5:J10003) -> 1.5530207
B24: 55+ | C24: =COUNTIF(DATA!K6:K1004,B24) -> 17 | D24: =SUMIF(DATA!K6:K10004,REPORTING!B24,DATA!F6:F1004) -> 1284616 | E24: =SUMIF(DATA!K6:K1004,REPORTING!B24,DATA!I6:I10004) -> 252587 | F24: =AVERAGEIF(DATA!K6:K10004,REPORTING!B24,DATA!H6:H1004) -> 0.033058824 | G24: =AVERAGEIF(DATA!K6:K10004,REPORTING!B24,DATA!J6:J10004) -> 1.8011322
C28: Recherche Campagne
B29: Entrer ID Campagne : | C29: Réseau Social | D29: Date de début | E29: Budget | F29: ROI
B30: 45 | C30: =_xlfn.XLOOKUP(B30,DATA!A2:A1000,DATA!B2:B1000,"faux") -> Instagram | D30: =_xlfn.XLOOKUP(B30,DATA!A2:A1000,DATA!C2:C1000) -> 44524.574 | E30: =_xlfn.XLOOKUP(B30,DATA!A2:A1000,DATA!E2:E1000) -> 8856 | F30: =_xlfn.XLOOKUP(B30,DATA!A2:A1000,DATA!J2:J1000) -> 0.66440831
B34: Performances par Intérêt
B35: Centre d'Intérêt | C35: Nombre total de campagnes | D35: Total des vues | E35: Total des ventes générées | F35: ROI Moyen
B36: Beauté | C36: =COUNTIF(DATA!M2:M1000,REPORTING!B36) -> 23 | D36: =SUMIF(DATA!M2:M10000,REPORTING!B36,DATA!F2:F1000) -> 1216167 | E36: =SUMIF(DATA!M2:M10000,REPORTING!B36,DATA!I2:I10000) -> 294810 | F36: =AVERAGEIF(DATA!M2:M1000,REPORTING!B36,DATA!J2:J1000) -> 1.7018403
B37: Santé | C37: =COUNTIF(DATA!M3:M1001,REPORTING!B37) -> 23 | D37: =SUMIF(DATA!M3:M10001,REPORTING!B37,DATA!F3:F1001) -> 1312367 | E37: =SUMIF(DATA!M3:M10001,REPORTING!B37,DATA!I3:I10001) -> 321875 | F37: =AVERAGEIF(DATA!M3:M1001,REPORTING!B37,DATA!J3:J1001) -> 1.9620465
B38: Lifestyle | C38: =COUNTIF(DATA!M4:M1002,REPORTING!B38) -> 22 | D38: =SUMIF(DATA!M4:M10002,REPORTING!B38,DATA!F4:F1002) -> 1024621 | E38: =SUMIF(DATA!M4:M10002,REPORTING!B38,DATA!I4:I10002) -> 405530 | F38: =AVERAGEIF(DATA!M4:M1002,REPORTING!B38,DATA!J4:J1002) -> 1.7252061
B39: Fitness | C39: =COUNTIF(DATA!M5:M1003,REPORTING!B39) -> 18 | D39: =SUMIF(DATA!M5:M10003,REPORTING!B39,DATA!F5:F1003) -> 992029 | E39: =SUMIF(DATA!M5:M10003,REPORTING!B39,DATA!I5:I10003) -> 188467 | F39: =AVERAGEIF(DATA!M5:M1003,REPORTING!B39,DATA!J5:J1003) -> 1.2948474
B40: Mode | C40: =COUNTIF(DATA!M6:M1004,REPORTING!B40) -> 19 | D40: =SUMIF(DATA!M6:M10004,REPORTING!B40,DATA!F6:F1004) -> 1015447 | E40: =SUMIF(DATA!M6:M10004,REPORTING!B40,DATA!I6:I10004) -> 259371 | F40: =AVERAGEIF(DATA!M6:M1004,REPORTING!B40,DATA!J6:J1004) -> 1.2802127
B43: Performances Sexe & Âge
B44: Sexe et Tranche d'âge | C44: Nombre total de campagnes | D44: Total des Vues | E44: Total des Ventes Générées (€) | F44: ROI Moyen (%)
B45: Femme | C45: 57 | D45: 3426042 | E45: 827006 | F45: 1.7416835
B46: Homme | C46: 48 | D46: 2134589 | E46: 643047 | F46: 1.4704013
B47: Total général | C47: 105 | D47: 5560631 | E47: 1470053 | F47: 1.6176688

Sheet TCD
B3: Nombre de ID Campagne | D3: Somme de Ventes Générées (€)
B4: 105 | D4: 1470053
B7: Somme de Budget de la Campagne (€)
B8: 561256
B11: Moyenne de Taux de Conversion (%)
B12: 0.090665714
B15: Moyenne de ROI (%)
B16: 1.6176688
B19: Étiquettes de lignes | C19: Somme de Ventes Générées (€) | G19: Étiquettes de lignes | H19: Moyenne de ROI (%)
B20: Facebook | C20: 497803 | G20: Facebook | H20: 1.6103558
B21: Instagram | C21: 561028 | G21: Instagram | H21: 1.4655934
B22: Twitter | C22: 411222 | G22: Twitter | H22: 1.8497531
B23: Total général | C23: 1470053 | G23: Total général | H23: 1.6176688
B43: Sexe et Tranche d'âge | C43: Total des Ventes Générées (€)
B44: Femme | C44: 827006
B45: Homme | C45: 643047
B46: Total général | C46: 1470053
B49: Sexe et Tranche d'âge | C49: Total des Ventes Générées (€)
B50: 18-24 | C50: 398209
B51: 25-34 | C51: 274382
B52: 35-44 | C52: 270590
B53: 45-54 | C53: 274285
B54: 55+ | C54: 252587
B55: Total général | C55: 1470053
B58: Sexe et Tranche d'âge | C58: Moyenne de Taux de Conversion (%)
B59: 18-24 | C59: 0.11618
B60: 25-34 | C60: 0.1353913
B61: 35-44 | C61: 0.065416667
B62: 45-54 | C62: 0.080086364
B63: 55+ | C63: 0.033058824
B64: Total général | C64: 0.090665714
B67: Sexe et Tranche d'âge | C67: Moyenne de Taux de Conversion (%)
B68: Femme | C68: 0.06135614
B69: Homme | C69: 0.12547083
B70: Total général | C70: 0.090665714
B78: Sexe et Tranche d'âge | C78: Somme de Ventes Générées (€) | D78: Moyenne de ROI (%)
B79: Beauté | C79: 294810 | D79: 1.7018403
B80: Fitness | C80: 188467 | D80: 1.2948474
B81: Lifestyle | C81: 405530 | D81: 1.7252061
B82: Mode | C82: 259371 | D82: 1.2802127
...

Sheet DASHBOARD

Sheet CONCLUSIONS

Sheet QCM
D2: Question 1 : Quelle affirmation décrit le mieux la science des données ?
C3: FALSE | D3: A) L'étude de techniques mathématiques avancées
C4: FALSE | D4: B) L'art de raconter des histoires avec des données
C5: TRUE | D5: C) L'analyse de grandes quantités de données pour en tirer des insights
C6: FALSE | D6: D) La programmation de logiciels pour le traitement de données
D8: Question 2 : Quel est le principal avantage de l'utilisation de modèles prédictifs en science des données ?
C9: FALSE | D9: A) Réduire les coûts de stockage des données
C10: TRUE | D10: B) Prédire des tendances et comportements futurs
C11: FALSE | D11: C) Améliorer la qualité graphique des présentations de données
C12: FALSE | D12: D) Augmenter la vitesse de calcul des ordinateurs
D14: Question 3 : Quelle définition correspond le mieux à la moyenne ?
C15: FALSE | D15: A) La valeur centrale d’un ensemble de données.
C16: TRUE | D16: B) La somme de toutes les valeurs divisée par le nombre de valeurs.
C17: FALSE | D17: C) La valeur qui apparaît le plus souvent
D19: Question 4 : Quelle est la principale différence entre corrélation et causalité ?
C20: FALSE | D20: A) La corrélation prouve qu’un événement cause un autre.
C21: TRUE | D21: B) La causalité implique une relation de cause à effet, tandis que la corrélation indique simplement une relation entre deux variables.
C22: FALSE | D22: C) Corrélation et causalité sont synonymes.
D24: Question 5 : Quelle phrase illustre une erreur de confusion entre corrélation et causalité ?
C25: TRUE | D25: A) Plus il y a de glaces vendues, plus il y a de noyades, donc les glaces causent les noyades.
C26: FALSE | D26: B) Plus on étudie, meilleures sont les notes.
C27: FALSE | D27: C) Moins on fait de sport, plus on prend du poids
D29: Question 6 : Quelle affirmation illustre la différence entre données structurées et non structurées ?
C30: TRUE | D30: A) Les données structurées sont organisées en tableaux, les non structurées incluent des images, vidéos, et textes libres
C31: FALSE | D31: B) Les données non structurées sont toujours numériques
C32: FALSE | D32: C) Les données structurées ne peuvent pas être analysées
D34: Question 7 : Quelle étape du parcours des données consiste à détecter des tendances à l’aide d’outils de visualisation ?
C35: FALSE | D35: A) Collecte
C36: TRUE | D36: B) Exploration et visualisation
C37: FALSE | D37: C) Prise de décision
D39: Question 8 : Quel métier se concentre principalement sur la création d’infrastructures de données ?
C40: FALSE | D40: A) Data Analyst
C41: TRUE | D41: B) Data Engineer
C42: FALSE | D42: C) Data Scientist
D44: Question 9 : Quelle notion décrit la valeur centrale d’un ensemble de données ordonnées ?
C45: FALSE | D45: A) Moyenne
C46: TRUE | D46: B) Médiane
C47: FALSE | D47: C) Mode
D49: Question 10 : Pourquoi l’éthique des données est-elle essentielle ?
C50: FALSE | D50: A) Pour maximiser la collecte de données
...
